Workbook

Sheet Home
D1: =Data!G8 -> 65 | F1: TEAM NAME | G1: TOP 12 | H1: TOTAL | I1: RANK | K1: Team | L1: Points Gained Today | N1: Team | O1: Avg Increase
F2: Himanshu Warriors | G2: =HW!H18 -> 9002 | H2: =HW!H19 -> 10097 | I2: =RANK(G2,G:G, FALSE)+COUNTIF(G$2:G2,G2)-1 -> 1 | K2: HW | L2: =STATS!T87 -> 104 | N2: HW | O2: =(HW!H18)/D1 -> 138.49231
F3: Onkar Legends | G3: =Legends[[#Totals],[Points]] -> 8341 | H3: =OL!H18 -> 8882 | I3: =RANK(G3,G:G, FALSE)+COUNTIF(G$2:G3,G3)-1 -> 2 | K3: MC | L3: =STATS!T88 -> 134 | N3: MC | O3: =Challengers[[#Totals],[Points]]/D1 -> 96.076923
F4: Abhishek Strikers | G4: =Strikers[[#Totals],[Points]] -> 8155 | H4: =AS!H18 -> 8775 | I4: =RANK(G4,G:G, FALSE)+COUNTIF(G$2:G4,G4)-1 -> 3 | K4: OL | L4: =STATS!T89 -> 161 | N4: OL | O4: =Legends[[#Totals],[Points]]/D1 -> 128.32308
F5: Pranav Astra | G5: =PA!H17 -> 7919 | H5: =PA!H18 -> 8142 | I5: =RANK(G5,G:G, FALSE)+COUNTIF(G$2:G5,G5)-1 -> 4 | K5: AS | L5: =STATS!T90 -> 30 | N5: AS | O5: =Strikers[[#Totals],[Points]]/D1 -> 125.46154
F6: Mehul Challengers | G6: =Challengers[[#Totals],[Points]] -> 6245 | H6: =MC!H18 -> 6579 | I6: =RANK(G6,G:G, FALSE)+COUNTIF(G$2:G6,G6)-1 -> 5 | K6: PA | L6: =STATS!T91 -> 160 | N6: PA | O6: =PA!H17/D1 -> 121.83077
A8: IPL - Crayons x S2 . | D8: Days Completed | F8: Himanshu Warriors Dominance: Himanshu Warriors finished at the top of the table with 9,002 points. Their success was driven by top performers like Shubman Gill (1,178 points) and KR (1,109 points). Steady Growth for Runners-up: Onkar Legends and Abhishek Strikers had a competitive run, finishing with 8,341 and 8,155 points respectively. Notably, Vaibhav Suryavanshi from Abhishek Strikers was one of the highest individual scorers with 1,211 points. Performance Gap: Mehul Challengers trailed the group, finishing with 6,245 points, despite a strong individual performance from Bhuvneshwar Kumar (1,051 points).
A21: Rules for Auction
A22: Player Selection Rules:
B23: • | C23: Minimum Players: Each team must buy a minimum of 15 players during the auction.
B24: • | C24: Overseas Players: Each team must have at least 3 overseas players. | D24: Bowlers | E24: 3
B25: • | C25: Uncapped Players: Each team must include at least 3 uncapped players. | D25: Batters | E25: 3
B26: • | C26: Special Rules: | D26: All-rounders | E26: 2
C27: Bowlers: Minimum 3 bowlers. | D27: Wicketkeeper | E27: 1
C28: Batters: Minimum 3 batters. | D28: Overseas | E28: 3
C29: All-rounders: Minimum 2 all-rounders. | D29: Uncapped | E29: 3
C30: Wicketkeeper: Minimum 1 wicketkeeper. | D30: =Data!G45 -> 31
B31: • | C31: Player List Submission: After the auction, each team must submit a final list of 15 players, adhering to the above rules. This list will be used for point calculation during the IPL tournament. Top 12 will be considered!
A32: Auction Participation:
B33: • | C33: Entry Fee: Each participant must pay an entry fee of ₹1000 to join the auction.
B34: • | C34: Winning Amount: The total collected entry fees will be distributed among the winners:
B35: • | C35: 1st Position: Team with the highest points at the end of the IPL tournament. (Winning amount: Rs.3000)
B36: • | C36: Runner-Up: Team with the second-highest points.(Winning amount: Rs.2000)
A37: Points Calculation and Winner:
B38: • | C38: Points will be calculated based on the performance of the selected players throughout the IPL tournament.
B39: • | C39: The team with the highest cumulative points will win 1st position, and the second-highest scorer will be declared the runner-up.
A40: Replacement Rules:
B41: • | C41: Each team must pre-select three players as potential replacements.
B42: • | C42: A capped player can be replaced only by another capped player.
B43: • | C43: An uncapped player can be replaced only by another uncapped player.
B44: • | C44: Any replacement must not violate the original team-composition rules, which remain unchanged
B45: • | C45: Replacement points will be calculated from the day Replacement happened. Past player points will not be replaced. (past player pt + replaced player pt)
B46: • | C46: Only one replacement allowed for 1 team per season
B47: In short: replacements are like-for-like, and the team balance stays exactly as defined.
A48: General Guidelines:
B49: • | C49: Ensure all team selections meet the mandatory player composition.
B50: • | C50: Be strategic in picking players to maximize points.
B51: • | C51: Happy Bidding and may the best team win!
A52: Note:
B53: In the event of an injury or if a player is ruled out, they can be replaced (without trade) before the IPL starts, i.e., before March 23rd.
...

Sheet HW
A1: Sr no. | B1: Name | C1: Type | D1: Overseas | E1: Wicketkeeper | F1: Capped/Uncapped | G1: Bid Taken(cr) | H1: Points | I1: IPL | J1: Number | K1: Value | L1: Compare | M1: Diff
A2: 1 | B2: Khaleel Ahmed + Rabada | C2: Bowler | G2: 1.75 | H2: =CSK!E5+GT!F12 -> 1048 | I2: CSK + GT | J2: =G2*100 -> 175 | K2: =H2-J2 -> 873 | L2: =Points!H82+Points!L97 -> 1048 | M2: =H2-L2 -> 0
A3: 2 | B3: Tristan Stubbs | C3: Batter | D3: Yes | E3: Yes | G3: 3.25 | H3: =DC!E5 -> 459 | I3: DC | J3: =G3*100 -> 325 | K3: =H3-J3 -> 134 | L3: =Points!H83 -> 459 | M3: =H3-L3 -> 0
A4: 3 | B4: Kuldeep Yadav | C4: Bowler | G4: 3.75 | H4: =DC!E6 -> 388 | I4: DC | J4: =G4*100 -> 375 | K4: =H4-J4 -> 13 | L4: =Points!H84 -> 388 | M4: =H4-L4 -> 0
A5: 4 | B5: Shubman Gill | C5: Batter | G5: 15.5 | H5: =GT!F5 -> 1178 | I5: GT | J5: =G5*100 -> 1550 | K5: =H5-J5 -> -372 | L5: =Points!H85 -> 1178 | M5: =H5-L5 -> 0
A6: 5 | B6: Mohammad Siraj | C6: Bowler | G6: 3.25 | H6: =GT!F6 -> 775 | I6: GT | J6: =G6*100 -> 325 | K6: =H6-J6 -> 450 | L6: =Points!H86 -> 775 | M6: =H6-L6 -> 0
A7: 7 | B7: Angkrish Raghuvanshi | C7: Batter | F7: Uncapped | G7: 5.55 | H7: =KKR!E5 -> 676 | I7: KKR | J7: =G7*100 -> 555 | K7: =H7-J7 -> 121 | L7: =Points!H87 -> 676 | M7: =H7-L7 -> 0
A8: 8 | B8: Mitchell Marsh | C8: All-Rounder | D8: Yes | G8: 7 | H8: =LSG!E5 -> 854 | I8: LSG | J8: =G8*100 -> 700 | K8: =H8-J8 -> 154 | L8: =Points!H88 -> 854 | M8: =H8-L8 -> 0
A9: 9 | B9: Nicholas Pooran | C9: Batter | D9: Yes | E9: Yes | G9: 10 | H9: =LSG!E6 -> 425 | I9: LSG | J9: =G9*100 -> 1000 | K9: =H9-J9 -> -575 | L9: =Points!H89 -> 425 | M9: =H9-L9 -> 0
A10: 13 | B10: Marcus Stoinis | C10: All-Rounder | D10: Yes | G10: 2 | H10: =PBSK!E5 -> 415 | I10: PBSK | J10: =G10*100 -> 200 | K10: =H10-J10 -> 215 | L10: =Points!H90 -> 415 | M10: =H10-L10 -> 0
A11: 11 | B11: Prabhsimran Singh | C11: Batter | E11: Yes | F11: Uncapped | G11: 5.5 | H11: =PBSK!E6 -> 831 | I11: PBSK | J11: =G11*100 -> 550 | K11: =H11-J11 -> 281 | L11: =Points!H91 -> 831 | M11: =H11-L11 -> 0
A12: 12 | B12: Shashank Singh | C12: Batter | F12: Uncapped | G12: 3 | H12: =PBSK!E7 -> 350 | I12: PBSK | J12: =G12*100 -> 300 | K12: =H12-J12 -> 50 | L12: =Points!H92 -> 350 | M12: =H12-L12 -> 0
A13: 14 | B13: Jitesh Sharma | C13: Batter | E13: Yes | G13: 2.5 | H13: =RCB!E5 -> 357 | I13: RCB | J13: =G13*100 -> 250 | K13: =H13-J13 -> 107 | L13: =Points!H93 -> 357 | M13: =H13-L13 -> 0
A14: 6 | B14: Jofra Archer | C14: Bowler | D14: Yes | G14: 6 | H14: =RR!E5 -> 1083 | I14: RR | J14: =G14*100 -> 600 | K14: =H14-J14 -> 483 | L14: =Points!H94 -> 1083 | M14: =H14-L14 -> 0
A15: 15 | B15: Ravindra Jadeja | C15: All-Rounder | G15: 9.5 | H15: =RR!E6 -> 715 | I15: RR | J15: =G15*100 -> 950 | K15: =H15-J15 -> -235 | L15: =Points!H95 -> 715 | M15: =H15-L15 -> 0
A16: 10 | B16: Mohammed Shami | C16: Bowler | G16: 2 | H16: =LSG!E7 -> 543 | I16: LSG | J16: =G16*100 -> 200 | K16: =H16-J16 -> 343 | L16: =Points!H96 -> 543 | M16: =H16-L16 -> 0
G18: TOP 12 | H18: =SUM(LARGE(H2:H17, 1),LARGE(H2:H17,2),LARGE(H2:H17,3),LARGE(H2:H17,4),LARGE(H2:H17,5),LARGE(H2:H17, 6),LARGE(H2:H17,7),LARGE(H2:H17,8),LARGE(H2:H17,9),LARGE(H2:H17,10),LARGE(H2:H17,11),LARGE(H2:H17,12)) -> 9002 | I18: =IFERROR(__xludf.DUMMYFUNCTION("SUM(QUERY(H2:H16, ""SELECT Col1 WHERE Col1 IS NOT NULL ORDER BY Col1 DESC LIMIT 12"")) "),9002) -> 9002
G19: Total | H19: =SUM(Warriors[Points]) -> 10097
G20: Missed Top 12 Combo | H20: =IFERROR(__xludf.DUMMYFUNCTION("SUM(QUERY({H3:H16;H23:H100}, ""SELECT Col1 WHERE Col1 IS NOT NULL ORDER BY Col1 DESC LIMIT 12""))"),9600) -> 9600 | I20: Diffrence | J20: =H20-H18 -> 598
A21: Sr no. | B21: Name | C21: Type | D21: Overseas | E21: Wicketkeeper | F21: Capped/Uncapped | G21: Bid Taken(cr) | H21: Points | I21: IPL | J21: Number | K21: Value
A22: 1 | B22: Kagiso Rabada | C22: Bowler | D22: Yes | G22: 2 | H22: =GT!F12 -> 935 | I22: GT | J22: =G22*100 -> 200 | K22: =H22-J22 -> 735
A23: 2 | B23: Rinku Singh | C23: Batter | G23: 1.25 | H23: =KKR!E11 -> 536 | I23: KKR | J23: =G23*100 -> 125 | K23: =H23-J23 -> 411
A24: 3 | B24: Kartik Sharma | C24: Batter | E24: Yes | F24: Uncapped | G24: 0.55 | H24: =CSK!E14 -> 439 | I24: CSK | J24: =G24*100 -> 55 | K24: =H24-J24 -> 384
B25: KA | H25: =Points!H82 -> 113
B26: KR | H26: =Points!H97 -> 1109
N27: Himanshu Warriors
N28: Slow start but explosive growth from April onward.
N29: Took first place on 1 Apr.
N30: Regained the lead permanently on 28 Apr.
N31: Recorded the highest final score.
N32: Strongest late-tournament performer.
N34: Story: The ultimate comeback champions. And also one and only Defending champoin.
A50: Sr no. | B50: Name | C50: Type | D50: Overseas | E50: Wicketkeeper | F50: Capped/Uncapped | G50: Bid Taken(cr) | H50: Points | I50: IPL | J50: Number | K50: Value
A51: 1 | B51: Ashutosh Sharma | C51: All-Rounder | F51: Uncapped | G51: 0.3 | H51: =Extra!E5 -> 286 | I51: DC | J51: =G51*100 -> 30 | K51: =H51-J51 -> 256
A52: 2 | B52: Ben Duckett | C52: Batter | D52: Yes | E52: Yes | G52: 2 | H52: =Extra!E6 -> 0 | I52: DC | J52: =G52*100 -> 200 | K52: =H52-J52 -> -200
A53: 3 | B53: Corbin Bosch | C53: All-Rounder | D53: Yes | G53: 1.5 | H53: =Extra!E7 -> 507 | I53: MI | J53: =G53*100 -> 150 | K53: =H53-J53 -> 357
A54: 4 | B54: Tim David | C54: All-Rounder | D54: Yes | G54: 4 | H54: =Extra!E8 -> 510 | I54: RCB | J54: =G54*100 -> 400 | K54: =H54-J54 -> 110
A55: 5 | B55: Cooper Connolly | C55: All-Rounder | D55: Yes | G55: 2 | H55: =Extra!E9 -> 790 | I55: PBSK | J55: =G55*100 -> 200 | K55: =H55-J55 -> 590
A56: 6 | B56: Liam Livingstone | C56: All-Rounder | D56: Yes | G56: 2 | H56: =Extra!E10 -> 57 | I56: SRH | J56: =G56*100 -> 200 | K56: =H56-J56 -> -143
A57: 7 | B57: Vyshak Vijaykumar | C57: Bowler | F57: Uncapped | G57: 0.3 | H57: =Extra!E11 -> 267 | I57: PBSK | J57: =G57*100 -> 30 | K57: =H57-J57 -> 237
...

Sheet AS
A1: Sr no. | B1: Name | C1: Type | D1: Overseas | E1: Wicketkeeper | F1: Capped/Uncapped | G1: Bid Taken | H1: Points | I1: IPL | J1: Number | K1: Value | L1: Compare | M1: diff
A2: 2 | B2: Shivam Dube | C2: All-Rounder | G2: 3.25 | H2: =CSK!E10 -> 471 | I2: CSK | J2: =G2*100 -> 325 | K2: =H2-J2 -> 146 | L2: =Points!H5 -> 471 | M2: =H2-L2 -> 0
A3: 12 | B3: Sanju Samson | C3: Batter | E3: Yes | G3: 6 | H3: =CSK!E11 -> 770 | I3: CSK | J3: =G3*100 -> 600 | K3: =H3-J3 -> 170 | L3: =Points!H6 -> 770 | M3: =H3-L3 -> 0
A4: 3 | B4: Sai Sudharsan | C4: Batter | G4: 6.5 | H4: =GT!F9 -> 1089 | I4: GT | J4: =G4*100 -> 650 | K4: =H4-J4 -> 439 | L4: =Points!H7 -> 1089 | M4: =H4-L4 -> 0
A5: 4 | B5: Mohsin Khan | C5: Bowler | F5: Uncapped | G5: 0.3 | H5: =LSG!E11 -> 444 | I5: LSG | J5: =G5*100 -> 30 | K5: =H5-J5 -> 414 | L5: =Points!H8 -> 444 | M5: =H5-L5 -> 0
A6: 5 | B6: Tilak Varma | C6: Batter | G6: 5.5 | H6: =MI!E8 -> 629 | I6: MI | J6: =G6*100 -> 550 | K6: =H6-J6 -> 79 | L6: =Points!H9 -> 629 | M6: =H6-L6 -> 0
A7: 6 | B7: Quinton de Kock | C7: Batter | D7: Yes | G7: 3 | H7: =MI!E9 -> 221 | I7: MI | J7: =G7*100 -> 300 | K7: =H7-J7 -> -79 | L7: =Points!H10 -> 221 | M7: =H7-L7 -> 0
A8: 10 | B8: Jasprit Bumrah | C8: Bowler | G8: 11 | H8: =MI!E10 -> 301 | I8: MI | J8: =G8*100 -> 1100 | K8: =H8-J8 -> -799 | L8: =Points!H11 -> 301 | M8: =H8-L8 -> 0
A9: 1 | B9: Harpreet Brar | C9: All-Rounder | F9: Uncapped | G9: 0.3 | H9: =PBSK!E10 -> 98 | I9: PBSK | J9: =G9*100 -> 30 | K9: =H9-J9 -> 68 | L9: =Points!H12 -> 98 | M9: =H9-L9 -> 0
A10: 9 | B10: Yuzvendra Chahal | C10: Bowler | G10: 8.5 | H10: =PBSK!E11 -> 433 | I10: PBSK | J10: =G10*100 -> 850 | K10: =H10-J10 -> -417 | L10: =Points!H13 -> 433 | M10: =H10-L10 -> 0
A11: 11 | B11: Romario Shepherd | C11: All-Rounder | D11: Yes | G11: 2.5 | H11: =RCB!E11 -> 399 | I11: RCB | J11: =G11*100 -> 250 | K11: =H11-J11 -> 149 | L11: =Points!H14 -> 399 | M11: =H11-L11 -> 0
A12: 14 | B12: Vaibhav Suryavanshi | C12: All-Rounder | F12: Uncapped | G12: 7.55 | H12: =RR!E9 -> 1211 | I12: RR | J12: =G12*100 -> 755 | K12: =H12-J12 -> 456 | L12: =Points!H15 -> 1211 | M12: =H12-L12 -> 0
A13: 8 | B13: Ravi Bishnoi | C13: Bowler | G13: 6 | H13: =RR!E10 -> 401 | I13: RR | J13: =G13*100 -> 600 | K13: =H13-J13 -> -199 | L13: =Points!H16 -> 401 | M13: =H13-L13 -> 0
A14: 15 | B14: Abhishek Sharma | C14: All-Rounder | G14: 12.5 | H14: =SRH!E6 -> 955 | I14: SRH | J14: =G14*100 -> 1250 | K14: =H14-J14 -> -295 | L14: =Points!H17 -> 955 | M14: =H14-L14 -> 0
A15: 13 | B15: Ishan Kishan | C15: Batter | E15: Yes | G15: 10.5 | H15: =SRH!E7 -> 996 | I15: SRH | J15: =G15*100 -> 1050 | K15: =H15-J15 -> -54 | L15: =Points!H18 -> 996 | M15: =H15-L15 -> 0
A16: 3 | B16: Pat Cummins | C16: All-Rounder | D16: Yes | G16: 6 | H16: =SRH!E8 -> 357 | I16: SRH | J16: =G16*100 -> 600 | K16: =H16-J16 -> -243 | L16: =Points!H19 -> 357 | M16: =H16-L16 -> 0
G17: TOP 12 | H17: =SUM(LARGE(H2:H16, 1),LARGE(H2:H16,2),LARGE(H2:H16,3),LARGE(H2:H16,4),LARGE(H2:H16,5),LARGE(H2:H16, 6),LARGE(H2:H16,7),LARGE(H2:H16,8),LARGE(H2:H16,9),LARGE(H2:H16,10),LARGE(H2:H16,11),LARGE(H2:H16,12)) -> 8155
G18: TOTAL | H18: =SUM(Strikers[Points]) -> 8775
G20: Missed Top 12 Combo | H20: =IFERROR(__xludf.DUMMYFUNCTION("SUM(QUERY({H2:H16;H22:H100}, ""SELECT Col1 WHERE Col1 IS NOT NULL ORDER BY Col1 DESC LIMIT 12""))"),8402) -> 8402 | I20: Diffrence | J20: =H20-Strikers[[#Totals],[Points]] -> 247 | N20: Abhishek Strikers
N21: Tournament leader at the start.
A22: Sr no. | B22: Name | C22: Type | D22: Overseas | E22: Wicketkeeper | F22: Capped/Uncapped | G22: Bid Taken(cr) | H22: Points | I22: IPL | J22: Number | K22: Value | N22: Dominated early April.
A23: 1 | B23: Rasikh Dar | C23: Bowler | F23: Uncapped | G23: 0.3 | H23: =RCB!E14 -> 604 | I23: RCB | J23: =G23*100 -> 30 | K23: =H23-J23 -> 574 | N23: Lost the lead to Pranav Astra.
A24: 2 | B24: Matheesha Pathirana | C24: Bowler | F24: Capped | G24: 7 | H24: =KKR!E13 -> 8 | I24: KKR | J24: =G24*100 -> 700 | K24: =H24-J24 -> -692 | N24: Mounted several comebacks and briefly returned to first in late April.
A25: 7 | B25: Nathan Ellis | C25: Bowler | G25: 3 | H25: =CSK!E15 -> 0 | I25: CSK | J25: 450 | K25: =H25-J25 -> -450 | N25: Finished third.
N27: Story: Early king who fought until the very end.
A49: Sr no. | B49: Name | C49: Type | D49: Overseas | E49: Wicketkeeper | F49: Capped/Uncapped | G49: Bid Taken(cr) | H49: Points | I49: IPL | J49: Number | K49: Value
A50: 1 | B50: Yudhvir Singh | C50: All-Rounder | F50: Uncapped | G50: 0.3 | H50: =Extra!E16 -> 0 | I50: RR | J50: =G50*100 -> 30 | K50: =H50-J50 -> -30

Sheet PA
A1: Sr no. | B1: Name | C1: Type | D1: Overseas | E1: Wicketkeeper | F1: Capped/Uncapped | G1: Bid Taken | H1: Points | I1: IPL | J1: Number | K1: Value | L1: Compare | M1: Diff
A2: 4 | B2: Dewald Brevis | C2: Batter | D2: Overseas | F2: Capped | G2: 5.5 | H2: =CSK!E12 -> 357 | I2: CSK | J2: =G2*100 -> 550 | K2: =H2-J2 -> -193 | L2: =Points!H61 -> 357 | M2: =H2-L2 -> 0
A3: 8 | B3: Noor Ahmad | C3: Bowler | D3: Overseas | F3: Capped | G3: 5 | H3: =CSK!E13 -> 520 | I3: CSK | J3: =G3*100 -> 500 | K3: =H3-J3 -> 20 | L3: =Points!H62 -> 520 | M3: =H3-L3 -> 0
A4: 3 | B4: Auqib Nabi | C4: All-Rounder | F4: Uncapped | G4: 0.3 | H4: =DC!E11 -> 56 | I4: DC | J4: =G4*100 -> 30 | K4: =H4-J4 -> 26 | L4: =Points!H63 -> 56 | M4: =H4-L4 -> 0
A5: 6 | B5: Jos Buttler | C5: Batter | D5: Overseas | E5: Wicketkeeper | F5: Capped | G5: 11.5 | H5: =GT!F10 -> 1037 | I5: GT | J5: =G5*100 -> 1150 | K5: =H5-J5 -> -113 | L5: =Points!H64 -> 1037 | M5: =H5-L5 -> 0
A6: 10 | B6: Prasidh Krishna | C6: Bowler | F6: Capped | G6: 4.75 | H6: =GT!F11 -> 572 | I6: GT | J6: =G6*100 -> 475 | K6: =H6-J6 -> 97 | L6: =Points!H65 -> 572 | M6: =H6-L6 -> 0
A7: 2 | B7: Vaibhav Arora | C7: Bowler | F7: Uncapped | G7: 4.05 | H7: =KKR!E10 -> 405 | I7: KKR | J7: =G7*100 -> 405 | K7: =H7-J7 -> 0 | L7: =Points!H66 -> 405 | M7: =H7-L7 -> 0
A8: 12 | B8: Aiden Markram | C8: All-Rounder | D8: Overseas | F8: Capped | G8: 4.25 | H8: =LSG!E12 -> 431 | I8: LSG | J8: =G8*100 -> 425 | K8: =H8-J8 -> 6 | L8: =Points!H67 -> 431 | M8: =H8-L8 -> 0
A9: 13 | B9: Will Jacks | C9: All-Rounder | D9: Overseas | F9: Capped | G9: 5.5 | H9: =MI!E11 -> 307 | I9: MI | J9: =G9*100 -> 550 | K9: =H9-J9 -> -243 | L9: =Points!H68 -> 307 | M9: =H9-L9 -> 0
A10: 1 | B10: Nehal Wadhera | C10: Batter | F10: Uncapped | G10: 7.05 | H10: =PBSK!E12 -> 127 | I10: PBSK | J10: =G10*100 -> 705 | K10: =H10-J10 -> -578 | L10: =Points!H69 -> 127 | M10: =H10-L10 -> 0
A11: 7 | B11: Shreyas Iyer | C11: Batter | F11: Capped | G11: 8.5 | H11: =PBSK!E13 -> 815 | I11: PBSK | J11: =G11*100 -> 850 | K11: =H11-J11 -> -35 | L11: =Points!H70 -> 815 | M11: =H11-L11 -> 0
A12: 9 | B12: Devdutt Padikkal | C12: Batter | F12: Capped | G12: 2 | H12: =RCB!E12 -> 835 | I12: RCB | J12: =G12*100 -> 200 | K12: =H12-J12 -> 635 | L12: =Points!H71 -> 835 | M12: =H12-L12 -> 0
A13: 11 | B13: Virat Kohli | C13: Batter | F13: Capped | G13: 17 | H13: =RCB!E13 -> 1060 | I13: RCB | J13: =G13*100 -> 1700 | K13: =H13-J13 -> -640 | L13: =Points!H72 -> 1060 | M13: =H13-L13 -> 0
A14: 5 | B14: Riyan Parag | C14: All-Rounder | F14: Capped | G14: 2.5 | H14: =RR!E11 -> 564 | I14: RR | J14: =G14*100 -> 250 | K14: =H14-J14 -> 314 | L14: =Points!H73 -> 564 | M14: =H14-L14 -> 0
A15: 14 | B15: Harshal Patel | C15: All-Rounder | F15: Capped | G15: 2 | H15: =SRH!E9 -> 40 | I15: SRH | J15: =G15*100 -> 200 | K15: =H15-J15 -> -160 | L15: =Points!H74 -> 40 | M15: =H15-L15 -> 0
A16: 15 | B16: Heinrich Klaasen | C16: Batter | D16: Overseas | E16: Wicketkeeper | F16: Capped | G16: 6.5 | H16: =SRH!E10 -> 1016 | I16: SRH | J16: =G16*100 -> 650 | K16: =H16-J16 -> 366 | L16: =Points!H75 -> 1016 | M16: =H16-L16 -> 0
G17: TOP 12 | H17: =SUM(LARGE(H2:H16, 1),LARGE(H2:H16,2),LARGE(H2:H16,3),LARGE(H2:H16,4),LARGE(H2:H16,5),LARGE(H2:H16, 6),LARGE(H2:H16,7),LARGE(H2:H16,8),LARGE(H2:H16,9),LARGE(H2:H16,10),LARGE(H2:H16,11),LARGE(H2:H16,12)) -> 7919
G18: TOTAL | H18: =SUM(H2:H16) -> 8142
G19: Missed Top 12 Combo | H19: =IFERROR(__xludf.DUMMYFUNCTION("SUM(QUERY({H1:H16;H21:H99}, ""SELECT Col1 WHERE Col1 IS NOT NULL ORDER BY Col1 DESC LIMIT 12""))"),8038) -> 8038 | I19: Diffrence | J19: =H19-H17 -> 119
M22: Pranav Astra
A23: Sr no. | B23: Name | C23: Type | D23: Overseas | E23: Wicketkeeper | F23: Capped/Uncapped | G23: Bid Taken(cr) | H23: Points | I23: IPL | J23: Number | K23: Value | M23: One of the most consistent teams.
A24: 1 | B24: Nitish Rana | C24: All-Rounder | F24: Capped | G24: 2 | H24: =DC!E12 -> 381 | I24: DC | J24: =G24*100 -> 200 | K24: =H24-J24 -> 181 | M24: Dominated mid-April.
A25: 2 | B25: Trent Boult | C25: Bowler | F25: Capped | G25: 7 | H25: =MI!E13 -> 109 | I25: MI | J25: =G25*100 -> 700 | K25: =H25-J25 -> -591 | M25: Led for the longest uninterrupted stretch.
A26: 3 | B26: Venkatesh Iyer | C26: All-Rounder | F26: capped | G26: 5.5 | H26: =RCB!E15 -> 332 | I26: RCB | J26: =G26*100 -> 550 | K26: =H26-J26 -> -218 | M26: Stayed in the title race deep into the tournament.
M27: Eventually overtaken by faster-growing rivals.
M29: Story: The mid-season powerhouse.
A50: Sr no. | B50: Name | C50: Type | D50: Overseas | E50: Wicketkeeper | F50: Capped/Uncapped | G50: Bid Taken(cr) | H50: Points | I50: IPL | J50: Number | K50: Value
A51: 1 | B51: yash Dayal | C51: Bowler | F51: Uncapped | G51: 5.5 | H51: =Extra!E17 -> 0 | I51: RCB | J51: =G51*100 -> 550 | K51: =H51-J51 -> -550
A52: 2 | B52: Shardul Thakur | C52: All-Rounder | F52: Capped | G52: 0.75 | H52: =Extra!E18 -> 402 | I52: MI | J52: =G52*100 -> 75 | K52: =H52-J52 -> 327
A53: 3 | B53: Rahul Chahar | C53: Bowler | F53: Capped | G53: 1.75 | H53: =Extra!E19 -> 12 | I53: CSK | J53: =G53*100 -> 175 | K53: =H53-J53 -> -163

Sheet MC
A1: Sr no. | B1: Name | C1: Type | D1: Overseas | E1: Wicketkeeper | F1: Capped/Uncapped | G1: Bid Taken | H1: Points | I1: IPL | J1: Number | K1: Value | L1: Compare | M1: Diff
A2: 1 | B2: Ayush Mhatre + Sandeep Sharma | C2: Batter | F2: Uncapped | G2: 6.55 | H2: =CSK!E6+RR!E12 -> 312 | I2: CSK + RR | J2: 500 | K2: =H2-J2 -> -188 | L2: =Points!H24 -> 311 | M2: =H2-L2 -> 1
A3: 9 | B3: MS Dhoni | C3: Batter | E3: YES | F3: Uncapped | G3: 2 | H3: =CSK!E7 -> 0 | I3: CSK | J3: 1100 | K3: =H3-J3 -> -1100 | L3: =Points!H25 -> 0 | M3: =H3-L3 -> 0
A4: 7 | B4: Mitchell Starc | C4: Bowler | D4: YES | G4: 5.5 | H4: =DC!E7 -> 404 | I4: DC | J4: 250 | K4: =H4-J4 -> 154 | L4: =Points!H26 -> 404 | M4: =H4-L4 -> 0
A5: 4 | B5: Glenn Phillips | C5: Batter | D5: YES | G5: 1.5 | H5: =GT!F7 -> 165 | I5: GT | J5: 30 | K5: =H5-J5 -> 135 | L5: =Points!H27 -> 165 | M5: =H5-L5 -> 0
A6: 10 | B6: Sunil Narine | C6: All-Rounder | D6: YES | G6: 7.5 | H6: =KKR!E6 -> 688 | I6: KKR | J6: 600 | K6: =H6-J6 -> 88 | L6: =Points!H28 -> 688 | M6: =H6-L6 -> 0
A7: 12 | B7: Ajinkya Rahane | C7: Batter | G7: 4.75 | H7: =KKR!E7 -> 550 | I7: KKR | J7: 700 | K7: =H7-J7 -> -150 | L7: =Points!H29 -> 550 | M7: =H7-L7 -> 0
A8: 3 | B8: Ayush Badoni | C8: All-Rounder | F8: Uncapped | G8: 3 | H8: =LSG!E8 -> 348 | I8: LSG | J8: 450 | K8: =H8-J8 -> -102 | L8: =Points!H30 -> 348 | M8: =H8-L8 -> 0
A9: 6 | B9: Hardik Pandya | C9: All-Rounder | G9: 15 | H9: =MI!E5 -> 462 | I9: MI | J9: 800 | K9: =H9-J9 -> -338 | L9: =Points!H31 -> 462 | M9: =H9-L9 -> 0
A10: 5 | B10: Suryakumar Yadav | C10: Batter | G10: 16.5 | H10: =MI!E6 -> 432 | I10: MI | J10: 850 | K10: =H10-J10 -> -418 | L10: =Points!H32 -> 432 | M10: =H10-L10 -> 0
A11: 8 | B11: Rohit Sharma | C11: Batter | G11: 5.5 | H11: =MI!E7 -> 422 | I11: MI | J11: 1100 | K11: =H11-J11 -> -678 | L11: =Points!H33 -> 422 | M11: =H11-L11 -> 0
A12: 2 | B12: Priyansh Arya | C12: All-Rounder | F12: Uncapped | G12: 7.05 | H12: =PBSK!E8 -> 585 | I12: PBSK | J12: 300 | K12: =H12-J12 -> 285 | L12: =Points!H34 -> 585 | M12: =H12-L12 -> 0
A13: 13 | B13: Phil Salt | C13: Batter | D13: YES | E13: YES | G13: 6.5 | H13: =RCB!E6 -> 348 | I13: RCB | J13: 1000 | K13: =H13-J13 -> -652 | L13: =Points!H35 -> 348 | M13: =H13-L13 -> 0
A14: 11 | B14: Bhuvneshwar Kumar | C14: Bowler | G14: 3 | H14: =RCB!E7 -> 1051 | I14: RCB | J14: 850 | K14: =H14-J14 -> 201 | L14: =Points!H36 -> 1051 | M14: =H14-L14 -> 0
A15: 14 | B15: Josh Hazlewood | C15: Bowler | D15: YES | G15: 4 | H15: =RCB!E8 -> 643 | I15: RCB | J15: 750 | K15: =H15-J15 -> -107 | L15: =Points!H37 -> 643 | M15: =H15-L15 -> 0
A16: 15 | B16: Shimron Hetmyer | C16: Batter | D16: YES | G16: 0.75 | H16: =RR!E7 -> 169 | I16: RR | J16: 250 | K16: =H16-J16 -> -81 | L16: =Points!H38 -> 169 | M16: =H16-L16 -> 0
G17: TOP 12 | H17: =SUM(LARGE(H2:H16, 1),LARGE(H2:H16,2),LARGE(H2:H16,3),LARGE(H2:H16,4),LARGE(H2:H16,5),LARGE(H2:H16, 6),LARGE(H2:H16,7),LARGE(H2:H16,8),LARGE(H2:H16,9),LARGE(H2:H16,10),LARGE(H2:H16,11),LARGE(H2:H16,12)) -> 6245
G18: TOTAL | H18: =SUM(Challengers[Points]) -> 6579
G19: Missed Top 12 Combo | H19: =IFERROR(__xludf.DUMMYFUNCTION("SUM(QUERY({H1:H16;H21:H99}, ""SELECT Col1 WHERE Col1 IS NOT NULL ORDER BY Col1 DESC LIMIT 12""))"),6406) -> 6406 | I19: Diffrence | J19: =H19-Challengers[[#Totals],[Points]] -> 161 | M19: Mehul Challengers
M20: Excellent early momentum.
M21: Reached second place during the opening weeks.
A22: Sr no. | B22: Name | C22: Type | D22: Overseas | E22: Wicketkeeper | F22: Capped/Uncapped | G22: Bid Taken(cr) | H22: Points | I22: IPL | J22: Number | K22: Value | M22: Could not sustain the pace set by the leading teams.
A23: 1 | B23: Sandeep Sharma | C23: Bowler | G23: 2.5 | H23: =Points!H39 -> 193 | I23: RR | J23: =G23*100 -> 250 | K23: =H23-J23 -> -57 | M23: Continued steady growth but gradually fell behind.
A24: 2 | B24: Marco Jansen | C24: All-Rounder | G24: 8 | H24: =PBSK!E14 -> 473 | I24: PBSK | J24: =G24*100 -> 800 | K24: =H24-J24 -> -327
M25: Story: Fast starter, steady finisher.
A49: Sr no. | B49: Name | C49: Type | D49: Overseas | E49: Wicketkeeper | F49: Capped/Uncapped | G49: Bid Taken(cr) | H49: Points | I49: IPL | J49: Number | K49: Value

Sheet OL
A1: Sr no. | B1: Name | C1: Type | D1: Overseas | E1: Wicketkeeper | F1: Capped/Uncapped | G1: Bid Taken | H1: Points | I1: IPL | J1: Number | K1: Value | L1: Compare | M1: Diff
A2: 1 | B2: Prashant Veer | C2: All-Rounder | F2: Uncapped | G2: 3.05 | H2: =CSK!E8 -> 139 | I2: CSK | J2: =G2*100 -> 305 | K2: =H2-J2 -> -166 | L2: =Points!H41 -> 139 | M2: =H2-L2 -> 0
A3: 4 | B3: Ruturaj Gaikwad | C3: Batter | F3: Capped | G3: 12 | H3: =CSK!E9 -> 532 | I3: CSK | J3: =G3*100 -> 1200 | K3: =H3-J3 -> -668 | L3: =Points!H42 -> 532 | M3: =H3-L3 -> 0
A4: 6 | B4: Axar Patel | C4: All-Rounder | F4: Capped | G4: 8 | H4: =DC!E8 -> 724 | I4: DC | J4: =G4*100 -> 800 | K4: =H4-J4 -> -76 | L4: =Points!H43 -> 724 | M4: =H4-L4 -> 0
A5: 3 | B5: Abhishek Porel | C5: Batter | E5: yes | F5: Uncapped | G5: 0.8 | H5: =DC!E9 -> 157 | I5: DC | J5: =G5*100 -> 80 | K5: =H5-J5 -> 77 | L5: =Points!H44 -> 157 | M5: =H5-L5 -> 0
A6: 13 | B6: KL Rahul | C6: Batter | E6: yes | F6: Capped | G6: 9.5 | H6: =DC!E10 -> 903 | I6: DC | J6: =G6*100 -> 950 | K6: =H6-J6 -> -47 | L6: =Points!H45 -> 903 | M6: =H6-L6 -> 0
A7: 5 | B7: Rashid Khan | C7: Bowler | D7: yes | F7: Capped | G7: 5.5 | H7: =GT!F8 -> 874 | I7: GT | J7: =G7*100 -> 550 | K7: =H7-J7 -> 324 | L7: =Points!H46 -> 874 | M7: =H7-L7 -> 0
A8: 11 | B8: Cameron Green | C8: Batter | D8: yes | F8: Capped | G8: 7 | H8: =KKR!E8 -> 752 | I8: KKR | J8: =G8*100 -> 700 | K8: =H8-J8 -> 52 | L8: =Points!H47 -> 752 | M8: =H8-L8 -> 0
A9: 7 | B9: Varun Chakaravarthy | C9: Bowler | F9: Capped | G9: 4.75 | H9: =KKR!E9 -> 433 | I9: KKR | J9: =G9*100 -> 475 | K9: =H9-J9 -> -42 | L9: =Points!H48 -> 433 | M9: =H9-L9 -> 0
A10: 2 | B10: Digvesh Singh | C10: Bowler | F10: Uncapped | G10: 0.3 | H10: =LSG!E9 -> 245 | I10: LSG | J10: =G10*100 -> 30 | K10: =H10-J10 -> 215 | L10: =Points!H49 -> 245 | M10: =H10-L10 -> 0
A11: 9 | B11: Rishabh Pant | C11: Batter | E11: yes | F11: Capped | G11: 8.5 | H11: =LSG!E10 -> 560 | I11: LSG | J11: =G11*100 -> 850 | K11: =H11-J11 -> -290 | L11: =Points!H50 -> 560 | M11: =H11-L11 -> 0
A12: 12 | B12: Arshdeep Singh | C12: Bowler | F12: Capped | G12: 5 | H12: =PBSK!E9 -> 536 | I12: PBSK | J12: =G12*100 -> 500 | K12: =H12-J12 -> 36 | L12: =Points!H51 -> 536 | M12: =H12-L12 -> 0
A13: 15 | B13: Krunal Pandya | C13: All-Rounder | F13: Capped | G13: 2.5 | H13: =RCB!E9 -> 836 | I13: RCB | J13: =G13*100 -> 250 | K13: =H13-J13 -> 586 | L13: =Points!H52 -> 836 | M13: =H13-L13 -> 0
A14: 8 | B14: Rajat Patidar | C14: Batter | F14: Capped | G14: 3.75 | H14: =RCB!E10 -> 845 | I14: RCB | J14: =G14*100 -> 375 | K14: =H14-J14 -> 470 | L14: =Points!H53 -> 845 | M14: =H14-L14 -> 0
A15: 10 | B15: Yashaswi Jaiswal | C15: Batter | F15: Capped | G15: 11.5 | H15: =RR!E8 -> 693 | I15: RR | J15: =G15*100 -> 1150 | K15: =H15-J15 -> -457 | L15: =Points!H54 -> 693 | M15: =H15-L15 -> 0
A16: 14 | B16: Travis Head | C16: Batter | D16: yes | F16: Capped | G16: 8 | H16: =SRH!E5 -> 653 | I16: SRH | J16: =G16*100 -> 800 | K16: =H16-J16 -> -147 | L16: =Points!H55 -> 653 | M16: =H16-L16 -> 0
G17: TOP 12 | H17: =SUM(LARGE(H2:H16, 1),LARGE(H2:H16,2),LARGE(H2:H16,3),LARGE(H2:H16,4),LARGE(H2:H16,5),LARGE(H2:H16, 6),LARGE(H2:H16,7),LARGE(H2:H16,8),LARGE(H2:H16,9),LARGE(H2:H16,10),LARGE(H2:H16,11),LARGE(H2:H16,12)) -> 8341
G18: TOTAL | H18: =SUM(Legends[Points]) -> 8882
G19: Missed Top 12 Combo | H19: =IFERROR(__xludf.DUMMYFUNCTION("SUM(QUERY({H1:H16;H21:H99}, ""SELECT Col1 WHERE Col1 IS NOT NULL ORDER BY Col1 DESC LIMIT 12""))"),8960) -> 8960 | I19: Diffrence | J19: =H19-Legends[[#Totals],[Points]] -> 619 | M19: Onkar Legends
M20: Began near the bottom.
A21: Sr no. | B21: Name | C21: Type | D21: Overseas | E21: Wicketkeeper | F21: Capped/Uncapped | G21: Bid Taken(cr) | H21: Points | I21: IPL | J21: Number | K21: Value | M21: Consistently climbed throughout April.
A22: 1 | B22: Nitish Kumar Reddy | C22: Batter | F22: Capped | G22: 1.25 | H22: =SRH!E11 -> 798 | I22: SRH | J22: =G22*100 -> 125 | K22: =H22-J22 -> 673 | M22: Never truly dominated the lead but became stronger every week.
A23: 2 | B23: Naman Dhir | C23: Batter | F23: Uncapped | G23: 2.8 | H23: =MI!E12 -> 553 | I23: MI | J23: =G23*100 -> 280 | K23: =H23-J23 -> 273 | M23: Finished second after one of the tournament's best long-term growth curves.
A24: 3 | B24: Finn Allen | C24: Batter | E24: yes | F24: Capped | G24: 2 | H24: =KKR!E12 -> 552 | I24: KKR | J24: =G24*100 -> 200 | K24: =H24-J24 -> 352
M25: Story: The tournament's biggest climber.
A49: Sr no. | B49: Name | C49: Type | D49: Overseas | E49: Wicketkeeper | F49: Capped/Uncapped | G49: Bid Taken(cr) | H49: Points | I49: IPL | J49: Number | K49: Value
A50: 1 | B50: Rahul Tewatia | C50: All-Rounder | F50: Uncapped | G50: 0.75 | H50: =Extra!E14 -> 320 | I50: GT | J50: =G50*100 -> 75 | K50: =H50-J50 -> 245
A51: 2 | B51: Jason Holder | C51: All-Rounder | F51: Capped | G51: 2.25 | H51: =Extra!E15 -> 769 | I51: GT | J51: =G51*100 -> 225 | K51: =H51-J51 -> 544
J52: =G52*100 -> 0 | K52: =H52-J52 -> 0

Sheet Performance
A1: Name | B1: Team | C1: IPL | D1: Points | L1: Type | M1: Value | N1: Efficiency
A2: Prashant Veer | B2: OL | C2: CSK | D2: =OL!H2 -> 139 | L2: All-Rounder | M2: =OL!K2 -> -166 | N2: =D2/OL!J2 -> 0.4557377
A3: Ruturaj Gaikwad | B3: OL | C3: CSK | D3: =OL!H3 -> 532 | L3: Batter | M3: =OL!K3 -> -668 | N3: =D3/OL!J3 -> 0.44333333
A4: Axar Patel | B4: OL | C4: DC | D4: =OL!H4 -> 724 | L4: All-Rounder | M4: =OL!K4 -> -76 | N4: =D4/OL!J4 -> 0.905
A5: Abhishek Porel | B5: OL | C5: DC | D5: =OL!H5 -> 157 | L5: Batter | M5: =OL!K5 -> 77 | N5: =D5/OL!J5 -> 1.9625
A6: KL Rahul | B6: OL | C6: DC | D6: =OL!H6 -> 903 | L6: Batter | M6: =OL!K6 -> -47 | N6: =D6/OL!J6 -> 0.95052632
A7: Rashid Khan | B7: OL | C7: GT | D7: =OL!H7 -> 874 | L7: Bowler | M7: =OL!K7 -> 324 | N7: =D7/OL!J7 -> 1.5890909
A8: Cameron Green | B8: OL | C8: KKR | D8: =OL!H8 -> 752 | L8: Batter | M8: =OL!K8 -> 52 | N8: =D8/OL!J8 -> 1.0742857
A9: Varun Chakaravarthy | B9: OL | C9: KKR | D9: =OL!H9 -> 433 | L9: Bowler | M9: =OL!K9 -> -42 | N9: =D9/OL!J9 -> 0.91157895
A10: Digvesh Singh | B10: OL | C10: LSG | D10: =OL!H10 -> 245 | L10: Bowler | M10: =OL!K10 -> 215 | N10: =D10/OL!J10 -> 8.1666667
A11: Rishabh Pant | B11: OL | C11: LSG | D11: =OL!H11 -> 560 | L11: Batter | M11: =OL!K11 -> -290 | N11: =D11/OL!J11 -> 0.65882353
A12: Arshdeep Singh | B12: OL | C12: PBSK | D12: =OL!H12 -> 536 | L12: Bowler | M12: =OL!K12 -> 36 | N12: =D12/OL!J12 -> 1.072
A13: Krunal Pandya | B13: OL | C13: RCB | D13: =OL!H13 -> 836 | L13: All-Rounder | M13: =OL!K13 -> 586 | N13: =D13/OL!J13 -> 3.344
... A16: Travis Head | B16: OL | C16: SRH | D16: =OL!H16 -> 653 | L16: Batter | M16: =OL!K16 -> -147 | N16: =D16/OL!J16 -> 0.81625
A17: Khaleel + Rabada | B17: HW | C17: CSK/GT | D17: =HW!H2 -> 1048 | L17: Bowler | M17: =HW!K2 -> 873 | N17: =D17/HW!J2 -> 5.9885714
A18: Tristan Stubbs | B18: HW | C18: DC | D18: =HW!H3 -> 459 | L18: Batter | M18: =HW!K3 -> 134 | N18: =D18/HW!J3 -> 1.4123077
A19: Kuldeep Yadav | B19: HW | C19: DC | D19: =HW!H4 -> 388 | L19: Bowler | M19: =HW!K4 -> 13 | N19: =D19/HW!J4 -> 1.0346667
A20: Shubman Gill | B20: HW | C20: GT | D20: =HW!H5 -> 1178 | L20: Batter | M20: =HW!K5 -> -372 | N20: =D20/HW!J5 -> 0.76
A21: Mohammad Siraj | B21: HW | C21: GT | D21: =HW!H6 -> 775 | L21: Bowler | M21: =HW!K6 -> 450 | N21: =D21/HW!J6 -> 2.3846154
A22: Angkrish Raghuvanshi | B22: HW | C22: KKR | D22: =HW!H7 -> 676 | L22: Batter | M22: =HW!K7 -> 121 | N22: =D22/HW!J7 -> 1.218018
A23: Mitchell Marsh | B23: HW | C23: LSG | D23: =HW!H8 -> 854 | L23: All-Rounder | M23: =HW!K8 -> 154 | N23: =D23/HW!J8 -> 1.22
A24: Nicholas Pooran | B24: HW | C24: LSG | D24: =HW!H9 -> 425 | L24: Batter | M24: =HW!K9 -> -575 | N24: =D24/HW!J9 -> 0.425
A25: Marcus Stoinis | B25: HW | C25: PBSK | D25: =HW!H10 -> 415 | L25: All-Rounder | M25: =HW!K10 -> 215 | N25: =D25/HW!J10 -> 2.075
A26: Prabhsimran Singh | B26: HW | C26: PBSK | D26: =HW!H11 -> 831 | L26: Batter | M26: =HW!K11 -> 281 | N26: =D26/HW!J11 -> 1.5109091
A27: Shashank Singh | B27: HW | C27: PBSK | D27: =HW!H12 -> 350 | L27: Batter | M27: =HW!K12 -> 50 | N27: =D27/HW!J12 -> 1.1666667
A28: Jitesh Sharma | B28: HW | C28: RCB | D28: =HW!H13 -> 357 | L28: Batter | M28: =HW!K13 -> 107 | N28: =D28/HW!J13 -> 1.428
... A31: Mohammed Shami | B31: HW | C31: LSG | D31: =HW!H16 -> 543 | L31: Bowler | M31: =HW!K16 -> 343 | N31: =D31/HW!J16 -> 2.715
A32: Dewald Brevis | B32: PA | C32: CSK | D32: =PA!H2 -> 357 | L32: Batter | M32: =PA!K2 -> -193 | N32: =D32/PA!J2 -> 0.64909091
A33: Noor Ahmad | B33: PA | C33: CSK | D33: =PA!H3 -> 520 | L33: Bowler | M33: =PA!K3 -> 20 | N33: =D33/PA!J3 -> 1.04
A34: Auqib Nabi | B34: PA | C34: DC | D34: =PA!H4 -> 56 | L34: All-Rounder | M34: =PA!K4 -> 26 | N34: =D34/PA!J4 -> 1.8666667
A35: Jos Buttler | B35: PA | C35: GT | D35: =PA!H5 -> 1037 | L35: Batter | M35: =PA!K5 -> -113 | N35: =D35/PA!J5 -> 0.90173913
A36: Prasidh Krishna | B36: PA | C36: GT | D36: =PA!H6 -> 572 | L36: Bowler | M36: =PA!K6 -> 97 | N36: =D36/PA!J6 -> 1.2042105
A37: Vaibhav Arora | B37: PA | C37: KKR | D37: =PA!H7 -> 405 | L37: Bowler | M37: =PA!K7 -> 0 | N37: =D37/PA!J7 -> 1
A38: Aiden Markram | B38: PA | C38: LSG | D38: =PA!H8 -> 431 | L38: All-Rounder | M38: =PA!K8 -> 6 | N38: =D38/PA!J8 -> 1.0141176
A39: Will Jacks | B39: PA | C39: MI | D39: =PA!H9 -> 307 | L39: All-Rounder | M39: =PA!K9 -> -243 | N39: =D39/PA!J9 -> 0.55818182
A40: Nehal Wadhera | B40: PA | C40: PBSK | D40: =PA!H10 -> 127 | L40: Batter | M40: =PA!K10 -> -578 | N40: =D40/PA!J10 -> 0.18014184
A41: Shreyas Iyer | B41: PA | C41: PBSK | D41: =PA!H11 -> 815 | L41: Batter | M41: =PA!K11 -> -35 | N41: =D41/PA!J11 -> 0.95882353
A42: Devdutt Padikkal | B42: PA | C42: RCB | D42: =PA!H12 -> 835 | L42: Batter | M42: =PA!K12 -> 635 | N42: =D42/PA!J12 -> 4.175
A43: Virat Kohli | B43: PA | C43: RCB | D43: =PA!H13 -> 1060 | L43: Batter | M43: =PA!K13 -> -640 | N43: =D43/PA!J13 -> 0.62352941
... A46: Heinrich Klaasen | B46: PA | C46: SRH | D46: =PA!H16 -> 1016 | L46: Batter | M46: =PA!K16 -> 366 | N46: =D46/PA!J16 -> 1.5630769
...

Sheet STATS
A1: Sr.No. | B1: Team Name | C1: TOP 12 | D1: TOTAL | E1: Ranking
A2: 2 | B2: Himanshu Warriors | C2: =HW!H18 -> 9002 | D2: =HW!H19 -> 10097 | E2: =RANK(C2,C:C, FALSE)+COUNTIF(C$2:C2,C2)-1 -> 1 | H2: =VLOOKUP("Himanshu Warriors", B:E, 4,FALSE) -> 1 | J2: =VLOOKUP("Mehul Challengers", B:E, 4,FALSE) -> 5 | N2: =VLOOKUP("Onkar Legends", B:E, 4,FALSE) -> 2 | P2: =VLOOKUP("Abhishek Strikers", B:E, 4,FALSE) -> 3 | T2: =VLOOKUP("Pranav Astra", B:E, 4,FALSE) -> 4
A3: 4 | B3: Onkar Legends | C3: =Legends[[#Totals],[Points]] -> 8341 | D3: =OL!H18 -> 8882 | E3: =RANK(C3,C:C, FALSE)+COUNTIF(C$2:C3,C3)-1 -> 2
A4: 1 | B4: Abhishek Strikers | C4: =Strikers[[#Totals],[Points]] -> 8155 | D4: =AS!H18 -> 8775 | E4: =RANK(C4,C:C, FALSE)+COUNTIF(C$2:C4,C4)-1 -> 3
A5: 3 | B5: Pranav Astra | C5: =PA!H17 -> 7919 | D5: =PA!H18 -> 8142 | E5: =RANK(C5,C:C, FALSE)+COUNTIF(C$2:C5,C5)-1 -> 4
A6: 5 | B6: Mehul Challengers | C6: =Challengers[[#Totals],[Points]] -> 6245 | D6: =MC!H18 -> 6579 | E6: =RANK(C6,C:C, FALSE)+COUNTIF(C$2:C6,C6)-1 -> 5
A10: ---- TOP PERFORMER ---- | G10: ---- TOP BATTER ---- | M10: ---- TOP BOWLER ---- | S10: ---- TOP ALL-ROUNDER ----
A11: Sr.No. | B11: =IFERROR(__xludf.DUMMYFUNCTION("QUERY(Performance!A:D, ""SELECT A, B, C, D ORDER BY D DESC LIMIT 12"", 1)"),"Name") -> Name | C11: =IFERROR(__xludf.DUMMYFUNCTION("""COMPUTED_VALUE"""),"Team") -> Team | D11: =IFERROR(__xludf.DUMMYFUNCTION("""COMPUTED_VALUE"""),"IPL") -> IPL | E11: =IFERROR(__xludf.DUMMYFUNCTION("""COMPUTED_VALUE"""),"Points") -> Points | G11: Sr.No. | H11: =IFERROR(__xludf.DUMMYFUNCTION("QUERY(Performance!A:L, ""SELECT A, B, C, D WHERE L = 'Batter' ORDER BY D DESC LIMIT 10"", 1) "),"Name") -> Name | I11: =IFERROR(__xludf.DUMMYFUNCTION("""COMPUTED_VALUE"""),"Team") -> Team | J11: =IFERROR(__xludf.DUMMYFUNCTION("""COMPUTED_VALUE"""),"IPL") -> IPL | K11: =IFERROR(__xludf.DUMMYFUNCTION("""COMPUTED_VALUE"""),"Points") -> Points | M11: Sr.No. | N11: =IFERROR(__xludf.DUMMYFUNCTION("QUERY(Performance!A:L, ""SELECT A, B, C, D WHERE L = 'Bowler' ORDER BY D DESC LIMIT 10"", 1) "),"Name") -> Name | O11: =IFERROR(__xludf.DUMMYFUNCTION("""COMPUTED_VALUE"""),"Team") -> Team | P11: =IFERROR(__xludf.DUMMYFUNCTION("""COMPUTED_VALUE"""),"IPL") -> IPL | Q11: =IFERROR(__xludf.DUMMYFUNCTION("""COMPUTED_VALUE"""),"Points") -> Points | S11: Sr.No. | T11: =IFERROR(__xludf.DUMMYFUNCTION("QUERY(Performance!A:L, ""SELECT A, B, C, D WHERE L = 'All-Rounder' ORDER BY D DESC LIMIT 10"", 1) "),"Name") -> Name | U11: =IFERROR(__xludf.DUMMYFUNCTION("""COMPUTED_VALUE"""),"Team") -> Team | V11: =IFERROR(__xludf.DUMMYFUNCTION("""COMPUTED_VALUE"""),"IPL") -> IPL | W11: =IFERROR(__xludf.DUMMYFUNCTION("""COMPUTED_VALUE"""),"Points") -> Points
A12: 1 | B12: =IFERROR(__xludf.DUMMYFUNCTION("""COMPUTED_VALUE"""),"Vaibhav Suryavanshi") -> Vaibhav Suryavanshi | C12: =IFERROR(__xludf.DUMMYFUNCTION("""COMPUTED_VALUE"""),"AS") -> AS | D12: =IFERROR(__xludf.DUMMYFUNCTION("""COMPUTED_VALUE"""),"RR") -> RR | E12: =IFERROR(__xludf.DUMMYFUNCTION("""COMPUTED_VALUE"""),1211) -> 1211 | G12: 1 | H12: =IFERROR(__xludf.DUMMYFUNCTION("""COMPUTED_VALUE"""),"Shubman Gill") -> Shubman Gill | I12: =IFERROR(__xludf.DUMMYFUNCTION("""COMPUTED_VALUE"""),"HW") -> HW | J12: =IFERROR(__xludf.DUMMYFUNCTION("""COMPUTED_VALUE"""),"GT") -> GT | K12: =IFERROR(__xludf.DUMMYFUNCTION("""COMPUTED_VALUE"""),1178) -> 1178 | M12: 1 | N12: =IFERROR(__xludf.DUMMYFUNCTION("""COMPUTED_VALUE"""),"Jofra Archer") -> Jofra Archer | O12: =IFERROR(__xludf.DUMMYFUNCTION("""COMPUTED_VALUE"""),"HW") -> HW | P12: =IFERROR(__xludf.DUMMYFUNCTION("""COMPUTED_VALUE"""),"RR") -> RR | Q12: =IFERROR(__xludf.DUMMYFUNCTION("""COMPUTED_VALUE"""),1083) -> 1083 | S12: 1 | T12: =IFERROR(__xludf.DUMMYFUNCTION("""COMPUTED_VALUE"""),"Vaibhav Suryavanshi") -> Vaibhav Suryavanshi | U12: =IFERROR(__xludf.DUMMYFUNCTION("""COMPUTED_VALUE"""),"AS") -> AS | V12: =IFERROR(__xludf.DUMMYFUNCTION("""COMPUTED_VALUE"""),"RR") -> RR | W12: =IFERROR(__xludf.DUMMYFUNCTION("""COMPUTED_VALUE"""),1211) -> 1211
A13: 2 | B13: =IFERROR(__xludf.DUMMYFUNCTION("""COMPUTED_VALUE"""),"Shubman Gill") -> Shubman Gill | C13: =IFERROR(__xludf.DUMMYFUNCTION("""COMPUTED_VALUE"""),"HW") -> HW | D13: =IFERROR(__xludf.DUMMYFUNCTION("""COMPUTED_VALUE"""),"GT") -> GT | E13: =IFERROR(__xludf.DUMMYFUNCTION("""COMPUTED_VALUE"""),1178) -> 1178 | G13: 2 | H13: =IFERROR(__xludf.DUMMYFUNCTION("""COMPUTED_VALUE"""),"Sai Sudharsan") -> Sai Sudharsan | I13: =IFERROR(__xludf.DUMMYFUNCTION("""COMPUTED_VALUE"""),"AS") -> AS | J13: =IFERROR(__xludf.DUMMYFUNCTION("""COMPUTED_VALUE"""),"GT") -> GT | K13: =IFERROR(__xludf.DUMMYFUNCTION("""COMPUTED_VALUE"""),1089) -> 1089 | M13: 2 | N13: =IFERROR(__xludf.DUMMYFUNCTION("""COMPUTED_VALUE"""),"Bhuvneshwar Kumar") -> Bhuvneshwar Kumar | O13: =IFERROR(__xludf.DUMMYFUNCTION("""COMPUTED_VALUE"""),"MC") -> MC | P13: =IFERROR(__xludf.DUMMYFUNCTION("""COMPUTED_VALUE"""),"RCB") -> RCB | Q13: =IFERROR(__xludf.DUMMYFUNCTION("""COMPUTED_VALUE"""),1051) -> 1051 | S13: 2 | T13: =IFERROR(__xludf.DUMMYFUNCTION("""COMPUTED_VALUE"""),"Abhishek Sharma") -> Abhishek Sharma | U13: =IFERROR(__xludf.DUMMYFUNCTION("""COMPUTED_VALUE"""),"AS") -> AS | V13: =IFERROR(__xludf.DUMMYFUNCTION("""COMPUTED_VALUE"""),"SRH") -> SRH | W13: =IFERROR(__xludf.DUMMYFUNCTION("""COMPUTED_VALUE"""),955) -> 955
A14: 3 | B14: =IFERROR(__xludf.DUMMYFUNCTION("""COMPUTED_VALUE"""),"Sai Sudharsan") -> Sai Sudharsan | C14: =IFERROR(__xludf.DUMMYFUNCTION("""COMPUTED_VALUE"""),"AS") -> AS | D14: =IFERROR(__xludf.DUMMYFUNCTION("""COMPUTED_VALUE"""),"GT") -> GT | E14: =IFERROR(__xludf.DUMMYFUNCTION("""COMPUTED_VALUE"""),1089) -> 1089 | G14: 3 | H14: =IFERROR(__xludf.DUMMYFUNCTION("""COMPUTED_VALUE"""),"Virat Kohli") -> Virat Kohli | I14: =IFERROR(__xludf.DUMMYFUNCTION("""COMPUTED_VALUE"""),"PA") -> PA | J14: =IFERROR(__xludf.DUMMYFUNCTION("""COMPUTED_VALUE"""),"RCB") -> RCB | K14: =IFERROR(__xludf.DUMMYFUNCTION("""COMPUTED_VALUE"""),1060) -> 1060 | M14: 3 | N14: =IFERROR(__xludf.DUMMYFUNCTION("""COMPUTED_VALUE"""),"Khaleel + Rabada") -> Khaleel + Rabada | O14: =IFERROR(__xludf.DUMMYFUNCTION("""COMPUTED_VALUE"""),"HW") -> HW | P14: =IFERROR(__xludf.DUMMYFUNCTION("""COMPUTED_VALUE"""),"CSK/GT") -> CSK/GT | Q14: =IFERROR(__xludf.DUMMYFUNCTION("""COMPUTED_VALUE"""),1048) -> 1048 | S14: 3 | T14: =IFERROR(__xludf.DUMMYFUNCTION("""COMPUTED_VALUE"""),"Mitchell Marsh") -> Mitchell Marsh | U14: =IFERROR(__xludf.DUMMYFUNCTION("""COMPUTED_VALUE"""),"HW") -> HW | V14: =IFERROR(__xludf.DUMMYFUNCTION("""COMPUTED_VALUE"""),"LSG") -> LSG | W14: =IFERROR(__xludf.DUMMYFUNCTION("""COMPUTED_VALUE"""),854) -> 854
A15: 4 | B15: =IFERROR(__xludf.DUMMYFUNCTION("""COMPUTED_VALUE"""),"Jofra Archer") -> Jofra Archer | C15: =IFERROR(__xludf.DUMMYFUNCTION("""COMPUTED_VALUE"""),"HW") -> HW | D15: =IFERROR(__xludf.DUMMYFUNCTION("""COMPUTED_VALUE"""),"RR") -> RR | E15: =IFERROR(__xludf.DUMMYFUNCTION("""COMPUTED_VALUE"""),1083) -> 1083 | G15: 4 | H15: =IFERROR(__xludf.DUMMYFUNCTION("""COMPUTED_VALUE"""),"Jos Buttler") -> Jos Buttler | I15: =IFERROR(__xludf.DUMMYFUNCTION("""COMPUTED_VALUE"""),"PA") -> PA | J15: =IFERROR(__xludf.DUMMYFUNCTION("""COMPUTED_VALUE"""),"GT") -> GT | K15: =IFERROR(__xludf.DUMMYFUNCTION("""COMPUTED_VALUE"""),1037) -> 1037 | M15: 4 | N15: =IFERROR(__xludf.DUMMYFUNCTION("""COMPUTED_VALUE"""),"Rashid Khan") -> Rashid Khan | O15: =IFERROR(__xludf.DUMMYFUNCTION("""COMPUTED_VALUE"""),"OL") -> OL | P15: =IFERROR(__xludf.DUMMYFUNCTION("""COMPUTED_VALUE"""),"GT") -> GT | Q15: =IFERROR(__xludf.DUMMYFUNCTION("""COMPUTED_VALUE"""),874) -> 874 | S15: 4 | T15: =IFERROR(__xludf.DUMMYFUNCTION("""COMPUTED_VALUE"""),"Krunal Pandya") -> Krunal Pandya | U15: =IFERROR(__xludf.DUMMYFUNCTION("""COMPUTED_VALUE"""),"OL") -> OL | V15: =IFERROR(__xludf.DUMMYFUNCTION("""COMPUTED_VALUE"""),"RCB") -> RCB | W15: =IFERROR(__xludf.DUMMYFUNCTION("""COMPUTED_VALUE"""),836) -> 836
A16: 5 | B16: =IFERROR(__xludf.DUMMYFUNCTION("""COMPUTED_VALUE"""),"Virat Kohli") -> Virat Kohli | C16: =IFERROR(__xludf.DUMMYFUNCTION("""COMPUTED_VALUE"""),"PA") -> PA | D16: =IFERROR(__xludf.DUMMYFUNCTION("""COMPUTED_VALUE"""),"RCB") -> RCB | E16: =IFERROR(__xludf.DUMMYFUNCTION("""COMPUTED_VALUE"""),1060) -> 1060 | G16: 5 | H16: =IFERROR(__xludf.DUMMYFUNCTION("""COMPUTED_VALUE"""),"Heinrich Klaasen") -> Heinrich Klaasen | I16: =IFERROR(__xludf.DUMMYFUNCTION("""COMPUTED_VALUE"""),"PA") -> PA | J16: =IFERROR(__xludf.DUMMYFUNCTION("""COMPUTED_VALUE"""),"SRH") -> SRH | K16: =IFERROR(__xludf.DUMMYFUNCTION("""COMPUTED_VALUE"""),1016) -> 1016 | M16: 5 | N16: =IFERROR(__xludf.DUMMYFUNCTION("""COMPUTED_VALUE"""),"Mohammad Siraj") -> Mohammad Siraj | O16: =IFERROR(__xludf.DUMMYFUNCTION("""COMPUTED_VALUE"""),"HW") -> HW | P16: =IFERROR(__xludf.DUMMYFUNCTION("""COMPUTED_VALUE"""),"GT") -> GT | Q16: =IFERROR(__xludf.DUMMYFUNCTION("""COMPUTED_VALUE"""),775) -> 775 | S16: 5 | T16: =IFERROR(__xludf.DUMMYFUNCTION("""COMPUTED_VALUE"""),"Axar Patel") -> Axar Patel | U16: =IFERROR(__xludf.DUMMYFUNCTION("""COMPUTED_VALUE"""),"OL") -> OL | V16: =IFERROR(__xludf.DUMMYFUNCTION("""COMPUTED_VALUE"""),"DC") -> DC | W16: =IFERROR(__xludf.DUMMYFUNCTION("""COMPUTED_VALUE"""),724) -> 724
A17: 6 | B17: =IFERROR(__xludf.DUMMYFUNCTION("""COMPUTED_VALUE"""),"Bhuvneshwar Kumar") -> Bhuvneshwar Kumar | C17: =IFERROR(__xludf.DUMMYFUNCTION("""COMPUTED_VALUE"""),"MC") -> MC | D17: =IFERROR(__xludf.DUMMYFUNCTION("""COMPUTED_VALUE"""),"RCB") -> RCB | E17: =IFERROR(__xludf.DUMMYFUNCTION("""COMPUTED_VALUE"""),1051) -> 1051 | G17: 6 | H17: =IFERROR(__xludf.DUMMYFUNCTION("""COMPUTED_VALUE"""),"Ishan Kishan") -> Ishan Kishan | I17: =IFERROR(__xludf.DUMMYFUNCTION("""COMPUTED_VALUE"""),"AS") -> AS | J17: =IFERROR(__xludf.DUMMYFUNCTION("""COMPUTED_VALUE"""),"SRH") -> SRH | K17: =IFERROR(__xludf.DUMMYFUNCTION("""COMPUTED_VALUE"""),996) -> 996 | M17: 6 | N17: =IFERROR(__xludf.DUMMYFUNCTION("""COMPUTED_VALUE"""),"Josh Hazlewood") -> Josh Hazlewood | O17: =IFERROR(__xludf.DUMMYFUNCTION("""COMPUTED_VALUE"""),"MC") -> MC | P17: =IFERROR(__xludf.DUMMYFUNCTION("""COMPUTED_VALUE"""),"RCB") -> RCB | Q17: =IFERROR(__xludf.DUMMYFUNCTION("""COMPUTED_VALUE"""),643) -> 643 | S17: 6 | T17: =IFERROR(__xludf.DUMMYFUNCTION("""COMPUTED_VALUE"""),"Ravindra Jadeja") -> Ravindra Jadeja | U17: =IFERROR(__xludf.DUMMYFUNCTION("""COMPUTED_VALUE"""),"HW") -> HW | V17: =IFERROR(__xludf.DUMMYFUNCTION("""COMPUTED_VALUE"""),"RR") -> RR | W17: =IFERROR(__xludf.DUMMYFUNCTION("""COMPUTED_VALUE"""),715) -> 715
A18: 7 | B18: =IFERROR(__xludf.DUMMYFUNCTION("""COMPUTED_VALUE"""),"Khaleel + Rabada") -> Khaleel + Rabada | C18: =IFERROR(__xludf.DUMMYFUNCTION("""COMPUTED_VALUE"""),"HW") -> HW | D18: =IFERROR(__xludf.DUMMYFUNCTION("""COMPUTED_VALUE"""),"CSK/GT") -> CSK/GT | E18: =IFERROR(__xludf.DUMMYFUNCTION("""COMPUTED_VALUE"""),1048) -> 1048 | G18: 7 | H18: =IFERROR(__xludf.DUMMYFUNCTION("""COMPUTED_VALUE"""),"KL Rahul") -> KL Rahul | I18: =IFERROR(__xludf.DUMMYFUNCTION("""COMPUTED_VALUE"""),"OL") -> OL | J18: =IFERROR(__xludf.DUMMYFUNCTION("""COMPUTED_VALUE"""),"DC") -> DC | K18: =IFERROR(__xludf.DUMMYFUNCTION("""COMPUTED_VALUE"""),903) -> 903 | M18: 7 | N18: =IFERROR(__xludf.DUMMYFUNCTION("""COMPUTED_VALUE"""),"Prasidh Krishna") -> Prasidh Krishna | O18: =IFERROR(__xludf.DUMMYFUNCTION("""COMPUTED_VALUE"""),"PA") -> PA | P18: =IFERROR(__xludf.DUMMYFUNCTION("""COMPUTED_VALUE"""),"GT") -> GT | Q18: =IFERROR(__xludf.DUMMYFUNCTION("""COMPUTED_VALUE"""),572) -> 572 | S18: 7 | T18: =IFERROR(__xludf.DUMMYFUNCTION("""COMPUTED_VALUE"""),"Sunil Narine") -> Sunil Narine | U18: =IFERROR(__xludf.DUMMYFUNCTION("""COMPUTED_VALUE"""),"MC") -> MC | V18: =IFERROR(__xludf.DUMMYFUNCTION("""COMPUTED_VALUE"""),"KKR") -> KKR | W18: =IFERROR(__xludf.DUMMYFUNCTION("""COMPUTED_VALUE"""),688) -> 688
A19: 8 | B19: =IFERROR(__xludf.DUMMYFUNCTION("""COMPUTED_VALUE"""),"Jos Buttler") -> Jos Buttler | C19: =IFERROR(__xludf.DUMMYFUNCTION("""COMPUTED_VALUE"""),"PA") -> PA | D19: =IFERROR(__xludf.DUMMYFUNCTION("""COMPUTED_VALUE"""),"GT") -> GT | E19: =IFERROR(__xludf.DUMMYFUNCTION("""COMPUTED_VALUE"""),1037) -> 1037 | G19: 8 | H19: =IFERROR(__xludf.DUMMYFUNCTION("""COMPUTED_VALUE"""),"Rajat Patidar") -> Rajat Patidar | I19: =IFERROR(__xludf.DUMMYFUNCTION("""COMPUTED_VALUE"""),"OL") -> OL | J19: =IFERROR(__xludf.DUMMYFUNCTION("""COMPUTED_VALUE"""),"RCB") -> RCB | K19: =IFERROR(__xludf.DUMMYFUNCTION("""COMPUTED_VALUE"""),845) -> 845 | M19: 8 | N19: =IFERROR(__xludf.DUMMYFUNCTION("""COMPUTED_VALUE"""),"Mohammed Shami") -> Mohammed Shami | O19: =IFERROR(__xludf.DUMMYFUNCTION("""COMPUTED_VALUE"""),"HW") -> HW | P19: =IFERROR(__xludf.DUMMYFUNCTION("""COMPUTED_VALUE"""),"LSG") -> LSG | Q19: =IFERROR(__xludf.DUMMYFUNCTION("""COMPUTED_VALUE"""),543) -> 543 | S19: 8 | T19: =IFERROR(__xludf.DUMMYFUNCTION("""COMPUTED_VALUE"""),"Priyansh Arya") -> Priyansh Arya | U19: =IFERROR(__xludf.DUMMYFUNCTION("""COMPUTED_VALUE"""),"MC") -> MC | V19: =IFERROR(__xludf.DUMMYFUNCTION("""COMPUTED_VALUE"""),"PBSK") -> PBSK | W19: =IFERROR(__xludf.DUMMYFUNCTION("""COMPUTED_VALUE"""),585) -> 585
A20: 9 | B20: =IFERROR(__xludf.DUMMYFUNCTION("""COMPUTED_VALUE"""),"Heinrich Klaasen") -> Heinrich Klaasen | C20: =IFERROR(__xludf.DUMMYFUNCTION("""COMPUTED_VALUE"""),"PA") -> PA | D20: =IFERROR(__xludf.DUMMYFUNCTION("""COMPUTED_VALUE"""),"SRH") -> SRH | E20: =IFERROR(__xludf.DUMMYFUNCTION("""COMPUTED_VALUE"""),1016) -> 1016 | G20: 9 | H20: =IFERROR(__xludf.DUMMYFUNCTION("""COMPUTED_VALUE"""),"Devdutt Padikkal") -> Devdutt Padikkal | I20: =IFERROR(__xludf.DUMMYFUNCTION("""COMPUTED_VALUE"""),"PA") -> PA | J20: =IFERROR(__xludf.DUMMYFUNCTION("""COMPUTED_VALUE"""),"RCB") -> RCB | K20: =IFERROR(__xludf.DUMMYFUNCTION("""COMPUTED_VALUE"""),835) -> 835 | M20: 9 | N20: =IFERROR(__xludf.DUMMYFUNCTION("""COMPUTED_VALUE"""),"Arshdeep Singh") -> Arshdeep Singh | O20: =IFERROR(__xludf.DUMMYFUNCTION("""COMPUTED_VALUE"""),"OL") -> OL | P20: =IFERROR(__xludf.DUMMYFUNCTION("""COMPUTED_VALUE"""),"PBSK") -> PBSK | Q20: =IFERROR(__xludf.DUMMYFUNCTION("""COMPUTED_VALUE"""),536) -> 536 | S20: 9 | T20: =IFERROR(__xludf.DUMMYFUNCTION("""COMPUTED_VALUE"""),"Riyan Parag") -> Riyan Parag | U20: =IFERROR(__xludf.DUMMYFUNCTION("""COMPUTED_VALUE"""),"PA") -> PA | V20: =IFERROR(__xludf.DUMMYFUNCTION("""COMPUTED_VALUE"""),"RR") -> RR | W20: =IFERROR(__xludf.DUMMYFUNCTION("""COMPUTED_VALUE"""),564) -> 564
A21: 10 | B21: =IFERROR(__xludf.DUMMYFUNCTION("""COMPUTED_VALUE"""),"Ishan Kishan") -> Ishan Kishan | C21: =IFERROR(__xludf.DUMMYFUNCTION("""COMPUTED_VALUE"""),"AS") -> AS | D21: =IFERROR(__xludf.DUMMYFUNCTION("""COMPUTED_VALUE"""),"SRH") -> SRH | E21: =IFERROR(__xludf.DUMMYFUNCTION("""COMPUTED_VALUE"""),996) -> 996 | G21: 10 | H21: =IFERROR(__xludf.DUMMYFUNCTION("""COMPUTED_VALUE"""),"Prabhsimran Singh") -> Prabhsimran Singh | I21: =IFERROR(__xludf.DUMMYFUNCTION("""COMPUTED_VALUE"""),"HW") -> HW | J21: =IFERROR(__xludf.DUMMYFUNCTION("""COMPUTED_VALUE"""),"PBSK") -> PBSK | K21: =IFERROR(__xludf.DUMMYFUNCTION("""COMPUTED_VALUE"""),831) -> 831 | M21: 10 | N21: =IFERROR(__xludf.DUMMYFUNCTION("""COMPUTED_VALUE"""),"Noor Ahmad") -> Noor Ahmad | O21: =IFERROR(__xludf.DUMMYFUNCTION("""COMPUTED_VALUE"""),"PA") -> PA | P21: =IFERROR(__xludf.DUMMYFUNCTION("""COMPUTED_VALUE"""),"CSK") -> CSK | Q21: =IFERROR(__xludf.DUMMYFUNCTION("""COMPUTED_VALUE"""),520) -> 520 | S21: 10 | T21: =IFERROR(__xludf.DUMMYFUNCTION("""COMPUTED_VALUE"""),"Shivam Dube") -> Shivam Dube | U21: =IFERROR(__xludf.DUMMYFUNCTION("""COMPUTED_VALUE"""),"AS") -> AS | V21: =IFERROR(__xludf.DUMMYFUNCTION("""COMPUTED_VALUE"""),"CSK") -> CSK | W21: =IFERROR(__xludf.DUMMYFUNCTION("""COMPUTED_VALUE"""),471) -> 471
A22: 11 | B22: =IFERROR(__xludf.DUMMYFUNCTION("""COMPUTED_VALUE"""),"Abhishek Sharma") -> Abhishek Sharma | C22: =IFERROR(__xludf.DUMMYFUNCTION("""COMPUTED_VALUE"""),"AS") -> AS | D22: =IFERROR(__xludf.DUMMYFUNCTION("""COMPUTED_VALUE"""),"SRH") -> SRH | E22: =IFERROR(__xludf.DUMMYFUNCTION("""COMPUTED_VALUE"""),955) -> 955
A23: 12 | B23: =IFERROR(__xludf.DUMMYFUNCTION("""COMPUTED_VALUE"""),"KL Rahul") -> KL Rahul | C23: =IFERROR(__xludf.DUMMYFUNCTION("""COMPUTED_VALUE"""),"OL") -> OL | D23: =IFERROR(__xludf.DUMMYFUNCTION("""COMPUTED_VALUE"""),"DC") -> DC | E23: =IFERROR(__xludf.DUMMYFUNCTION("""COMPUTED_VALUE"""),903) -> 903
A29: ---- Team Wise: TOP 1 PERFORMER ---- | G29: ---- Team Wise: TOP 1 BATTER---- | M29: ---- Team Wise: TOP 1 BOWLER---- | S29: ---- Team Wise: TOP 1 ALL-ROUNDER ----
A30: Team | B30: =IFERROR(__xludf.DUMMYFUNCTION("QUERY(HW!B:I, ""SELECT B, C, I, H where B is not null ORDER BY H DESC LIMIT 1"", 1)"),"Name") -> Name | C30: =IFERROR(__xludf.DUMMYFUNCTION("""COMPUTED_VALUE"""),"Type") -> Type | D30: =IFERROR(__xludf.DUMMYFUNCTION("""COMPUTED_VALUE"""),"IPL") -> IPL | E30: =IFERROR(__xludf.DUMMYFUNCTION("""COMPUTED_VALUE"""),"Points") -> Points | G30: Team | H30: =IFERROR(__xludf.DUMMYFUNCTION("QUERY(HW!B:I, ""SELECT B, C, I, H where B is not null AND C = 'Batter' ORDER BY H DESC LIMIT 1"", 1)"),"Name") -> Name | I30: =IFERROR(__xludf.DUMMYFUNCTION("""COMPUTED_VALUE"""),"Type") -> Type | J30: =IFERROR(__xludf.DUMMYFUNCTION("""COMPUTED_VALUE"""),"IPL") -> IPL | K30: =IFERROR(__xludf.DUMMYFUNCTION("""COMPUTED_VALUE"""),"Points") -> Points | M30: Team | N30: =IFERROR(__xludf.DUMMYFUNCTION("QUERY(HW!B:I, ""SELECT B, C, I, H where B is not null AND C = 'Bowler' ORDER BY H DESC LIMIT 1"", 1)"),"Name") -> Name | O30: =IFERROR(__xludf.DUMMYFUNCTION("""COMPUTED_VALUE"""),"Type") -> Type | P30: =IFERROR(__xludf.DUMMYFUNCTION("""COMPUTED_VALUE"""),"IPL") -> IPL | Q30: =IFERROR(__xludf.DUMMYFUNCTION("""COMPUTED_VALUE"""),"Points") -> Points | S30: Team | T30: =IFERROR(__xludf.DUMMYFUNCTION("QUERY(HW!B:I, ""SELECT B, C, I, H where B is not null AND C = 'All-Rounder' ORDER BY H DESC LIMIT 1"", 1)"),"Name") -> Name | U30: =IFERROR(__xludf.DUMMYFUNCTION("""COMPUTED_VALUE"""),"Type") -> Type | V30: =IFERROR(__xludf.DUMMYFUNCTION("""COMPUTED_VALUE"""),"IPL") -> IPL | W30: =IFERROR(__xludf.DUMMYFUNCTION("""COMPUTED_VALUE"""),"Points") -> Points
A31: HW | B31: =IFERROR(__xludf.DUMMYFUNCTION("""COMPUTED_VALUE"""),"Shubman Gill") -> Shubman Gill | C31: =IFERROR(__xludf.DUMMYFUNCTION("""COMPUTED_VALUE"""),"Batter") -> Batter | D31: =IFERROR(__xludf.DUMMYFUNCTION("""COMPUTED_VALUE"""),"GT") -> GT | E31: =IFERROR(__xludf.DUMMYFUNCTION("""COMPUTED_VALUE"""),1178) -> 1178 | G31: HW | H31: =IFERROR(__xludf.DUMMYFUNCTION("""COMPUTED_VALUE"""),"Shubman Gill") -> Shubman Gill | I31: =IFERROR(__xludf.DUMMYFUNCTION("""COMPUTED_VALUE"""),"Batter") -> Batter | J31: =IFERROR(__xludf.DUMMYFUNCTION("""COMPUTED_VALUE"""),"GT") -> GT | K31: =IFERROR(__xludf.DUMMYFUNCTION("""COMPUTED_VALUE"""),1178) -> 1178 | M31: HW | N31: =IFERROR(__xludf.DUMMYFUNCTION("""COMPUTED_VALUE"""),"Jofra Archer") -> Jofra Archer | O31: =IFERROR(__xludf.DUMMYFUNCTION("""COMPUTED_VALUE"""),"Bowler") -> Bowler | P31: =IFERROR(__xludf.DUMMYFUNCTION("""COMPUTED_VALUE"""),"RR") -> RR | Q31: =IFERROR(__xludf.DUMMYFUNCTION("""COMPUTED_VALUE"""),1083) -> 1083 | S31: HW | T31: =IFERROR(__xludf.DUMMYFUNCTION("""COMPUTED_VALUE"""),"Mitchell Marsh") -> Mitchell Marsh | U31: =IFERROR(__xludf.DUMMYFUNCTION("""COMPUTED_VALUE"""),"All-Rounder") -> All-Rounder | V31: =IFERROR(__xludf.DUMMYFUNCTION("""COMPUTED_VALUE"""),"LSG") -> LSG | W31: =IFERROR(__xludf.DUMMYFUNCTION("""COMPUTED_VALUE"""),854) -> 854
A32: PP | B32: =IFERROR(__xludf.DUMMYFUNCTION("ARRAYFORMULA(QUERY(PA!B:I, ""SELECT B, C, I, H where B is not null ORDER BY H DESC LIMIT 1"", 1)) "),"Name") -> Name | C32: =IFERROR(__xludf.DUMMYFUNCTION("""COMPUTED_VALUE"""),"Type") -> Type | D32: =IFERROR(__xludf.DUMMYFUNCTION("""COMPUTED_VALUE"""),"IPL") -> IPL | E32: =IFERROR(__xludf.DUMMYFUNCTION("""COMPUTED_VALUE"""),"Points") -> Points | G32: PP | H32: =IFERROR(__xludf.DUMMYFUNCTION("ARRAYFORMULA(QUERY(PA!B:I, ""SELECT B, C, I, H where B is not null AND C = 'Batter' ORDER BY H DESC LIMIT 1"", 1)) "),"Name") -> Name | I32: =IFERROR(__xludf.DUMMYFUNCTION("""COMPUTED_VALUE"""),"Type") -> Type | J32: =IFERROR(__xludf.DUMMYFUNCTION("""COMPUTED_VALUE"""),"IPL") -> IPL | K32: =IFERROR(__xludf.DUMMYFUNCTION("""COMPUTED_VALUE"""),"Points") -> Points | M32: PP | N32: =IFERROR(__xludf.DUMMYFUNCTION("ARRAYFORMULA(QUERY(PA!B:I, ""SELECT B, C, I, H where B is not null AND C = 'Bowler' ORDER BY H DESC LIMIT 1"", 1)) "),"Name") -> Name | O32: =IFERROR(__xludf.DUMMYFUNCTION("""COMPUTED_VALUE"""),"Type") -> Type | P32: =IFERROR(__xludf.DUMMYFUNCTION("""COMPUTED_VALUE"""),"IPL") -> IPL | Q32: =IFERROR(__xludf.DUMMYFUNCTION("""COMPUTED_VALUE"""),"Points") -> Points | S32: PP | T32: =IFERROR(__xludf.DUMMYFUNCTION("ARRAYFORMULA(QUERY(PA!B:I, ""SELECT B, C, I, H where B is not null AND C = 'All-Rounder' ORDER BY H DESC LIMIT 1"", 1))"),"Name") -> Name | U32: =IFERROR(__xludf.DUMMYFUNCTION("""COMPUTED_VALUE"""),"Type") -> Type | V32: =IFERROR(__xludf.DUMMYFUNCTION("""COMPUTED_VALUE"""),"IPL") -> IPL | W32: =IFERROR(__xludf.DUMMYFUNCTION("""COMPUTED_VALUE"""),"Points") -> Points
A33: PA | B33: =IFERROR(__xludf.DUMMYFUNCTION("""COMPUTED_VALUE"""),"Virat Kohli") -> Virat Kohli | C33: =IFERROR(__xludf.DUMMYFUNCTION("""COMPUTED_VALUE"""),"Batter") -> Batter | D33: =IFERROR(__xludf.DUMMYFUNCTION("""COMPUTED_VALUE"""),"RCB") -> RCB | E33: =IFERROR(__xludf.DUMMYFUNCTION("""COMPUTED_VALUE"""),1060) -> 1060 | G33: PA | H33: =IFERROR(__xludf.DUMMYFUNCTION("""COMPUTED_VALUE"""),"Virat Kohli") -> Virat Kohli | I33: =IFERROR(__xludf.DUMMYFUNCTION("""COMPUTED_VALUE"""),"Batter") -> Batter | J33: =IFERROR(__xludf.DUMMYFUNCTION("""COMPUTED_VALUE"""),"RCB") -> RCB | K33: =IFERROR(__xludf.DUMMYFUNCTION("""COMPUTED_VALUE"""),1060) -> 1060 | M33: PA | N33: =IFERROR(__xludf.DUMMYFUNCTION("""COMPUTED_VALUE"""),"Prasidh Krishna") -> Prasidh Krishna | O33: =IFERROR(__xludf.DUMMYFUNCTION("""COMPUTED_VALUE"""),"Bowler") -> Bowler | P33: =IFERROR(__xludf.DUMMYFUNCTION("""COMPUTED_VALUE"""),"GT") -> GT | Q33: =IFERROR(__xludf.DUMMYFUNCTION("""COMPUTED_VALUE"""),572) -> 572 | S33: PA | T33: =IFERROR(__xludf.DUMMYFUNCTION("""COMPUTED_VALUE"""),"Riyan Parag") -> Riyan Parag | U33: =IFERROR(__xludf.DUMMYFUNCTION("""COMPUTED_VALUE"""),"All-Rounder") -> All-Rounder | V33: =IFERROR(__xludf.DUMMYFUNCTION("""COMPUTED_VALUE"""),"RR") -> RR | W33: =IFERROR(__xludf.DUMMYFUNCTION("""COMPUTED_VALUE"""),564) -> 564
A34: MC | B34: =IFERROR(__xludf.DUMMYFUNCTION("QUERY(MC!B:I, ""SELECT B, C, I, H where B is not null ORDER BY H DESC LIMIT 1"", 1)"),"Name") -> Name | C34: =IFERROR(__xludf.DUMMYFUNCTION("""COMPUTED_VALUE"""),"Type") -> Type | D34: =IFERROR(__xludf.DUMMYFUNCTION("""COMPUTED_VALUE"""),"IPL") -> IPL | E34: =IFERROR(__xludf.DUMMYFUNCTION("""COMPUTED_VALUE"""),"Points") -> Points | G34: MC | H34: =IFERROR(__xludf.DUMMYFUNCTION("QUERY(MC!B:I, ""SELECT B, C, I, H where B is not null AND C = 'Batter' ORDER BY H DESC LIMIT 1"", 1)"),"Name") -> Name | I34: =IFERROR(__xludf.DUMMYFUNCTION("""COMPUTED_VALUE"""),"Type") -> Type | J34: =IFERROR(__xludf.DUMMYFUNCTION("""COMPUTED_VALUE"""),"IPL") -> IPL | K34: =IFERROR(__xludf.DUMMYFUNCTION("""COMPUTED_VALUE"""),"Points") -> Points | M34: MC | N34: =IFERROR(__xludf.DUMMYFUNCTION("QUERY(MC!B:I, ""SELECT B, C, I, H where B is not null AND C = 'Bowler' ORDER BY H DESC LIMIT 1"", 1)"),"Name") -> Name | O34: =IFERROR(__xludf.DUMMYFUNCTION("""COMPUTED_VALUE"""),"Type") -> Type | P34: =IFERROR(__xludf.DUMMYFUNCTION("""COMPUTED_VALUE"""),"IPL") -> IPL | Q34: =IFERROR(__xludf.DUMMYFUNCTION("""COMPUTED_VALUE"""),"Points") -> Points | S34: MC | T34: =IFERROR(__xludf.DUMMYFUNCTION("QUERY(MC!B:I, ""SELECT B, C, I, H where B is not null AND C = 'All-Rounder' ORDER BY H DESC LIMIT 1"", 1)"),"Name") -> Name | U34: =IFERROR(__xludf.DUMMYFUNCTION("""COMPUTED_VALUE"""),"Type") -> Type | V34: =IFERROR(__xludf.DUMMYFUNCTION("""COMPUTED_VALUE"""),"IPL") -> IPL | W34: =IFERROR(__xludf.DUMMYFUNCTION("""COMPUTED_VALUE"""),"Points") -> Points
A35: MC | B35: =IFERROR(__xludf.DUMMYFUNCTION("""COMPUTED_VALUE"""),"Bhuvneshwar Kumar") -> Bhuvneshwar Kumar | C35: =IFERROR(__xludf.DUMMYFUNCTION("""COMPUTED_VALUE"""),"Bowler") -> Bowler | D35: =IFERROR(__xludf.DUMMYFUNCTION("""COMPUTED_VALUE"""),"RCB") -> RCB | E35: =IFERROR(__xludf.DUMMYFUNCTION("""COMPUTED_VALUE"""),1051) -> 1051 | G35: MC | H35: =IFERROR(__xludf.DUMMYFUNCTION("""COMPUTED_VALUE"""),"Ajinkya Rahane") -> Ajinkya Rahane | I35: =IFERROR(__xludf.DUMMYFUNCTION("""COMPUTED_VALUE"""),"Batter") -> Batter | J35: =IFERROR(__xludf.DUMMYFUNCTION("""COMPUTED_VALUE"""),"KKR") -> KKR | K35: =IFERROR(__xludf.DUMMYFUNCTION("""COMPUTED_VALUE"""),550) -> 550 | M35: MC | N35: =IFERROR(__xludf.DUMMYFUNCTION("""COMPUTED_VALUE"""),"Bhuvneshwar Kumar") -> Bhuvneshwar Kumar | O35: =IFERROR(__xludf.DUMMYFUNCTION("""COMPUTED_VALUE"""),"Bowler") -> Bowler | P35: =IFERROR(__xludf.DUMMYFUNCTION("""COMPUTED_VALUE"""),"RCB") -> RCB | Q35: =IFERROR(__xludf.DUMMYFUNCTION("""COMPUTED_VALUE"""),1051) -> 1051 | S35: MC | T35: =IFERROR(__xludf.DUMMYFUNCTION("""COMPUTED_VALUE"""),"Sunil Narine") -> Sunil Narine | U35: =IFERROR(__xludf.DUMMYFUNCTION("""COMPUTED_VALUE"""),"All-Rounder") -> All-Rounder | V35: =IFERROR(__xludf.DUMMYFUNCTION("""COMPUTED_VALUE"""),"KKR") -> KKR | W35: =IFERROR(__xludf.DUMMYFUNCTION("""COMPUTED_VALUE"""),688) -> 688
